class exception4
{
 public static void main(String[] args)
{
 try
{
try
{
System.out.println("divide by Zero");
  int a=30/0;
 }
catch(ArithmeticException e)
{
 System.out.println(e);
 }
 try
{
 int a[]=new int[5];
  a[5]=10;
}
catch(ArrayIndexOutOfBoundsException e)
{
 System.out.println(e);
}

System.out.println("Statement");
}

catch(Exception e)
{
 System.out.println("error occured");
}
 System.out.println("after exception handled");
}
  }
